# Implementation Test Report
Generated on: 2025-04-16 23:12:49

## Summary
- Total Tests: 11
- Failures: 1
- Errors: 0
- Overall Status: FAILED

## Test Details

### Failures

#### Failure 1
```
Traceback (most recent call last):
  File "C:\Users\andri\AppData\Local\Programs\Python\Python311\Lib\unittest\mock.py", line 1378, in patched
    return func(*newargs, **newkeywargs)
           ^^^^^^^^^^^^^^^^^^^^^^^^^^^^^
  File "C:\Users\andri\OneDrive\Bureau\Rag 13.04.25\test_implementation_conflicts.py", line 558, in test_3_3_caching
    mock_redis_instance.setex.assert_called_with(f"session:{session_id}", 86400, user_id_session)
  File "C:\Users\andri\AppData\Local\Programs\Python\Python311\Lib\unittest\mock.py", line 930, in assert_called_with
    raise AssertionError(error_message)
AssertionError: expected call not found.
Expected: setex('session:a7df79ba-ac4a-48d1-9441-000fc9f05793', 86400, 'user_for_session')
  Actual: not called.

```
