# Implementation Test Report
Generated on: 2025-04-16 23:15:18

## Summary
- Total Tests: 11
- Failures: 0
- Errors: 10
- Overall Status: FAILED

## Test Details

### Errors

#### Error 1
```
Traceback (most recent call last):
  File "C:\Users\andri\OneDrive\Bureau\Rag 13.04.25\test_implementation_conflicts.py", line 77, in setUp
    self.auth_service = AuthService(db_manager=self.db_manager, cache_manager=self.cache_manager)
                        ^^^^^^^^^^^^^^^^^^^^^^^^^^^^^^^^^^^^^^^^^^^^^^^^^^^^^^^^^^^^^^^^^^^^^^^^^
TypeError: AuthService.__init__() got an unexpected keyword argument 'cache_manager'

```

#### Error 2
```
Traceback (most recent call last):
  File "C:\Users\andri\OneDrive\Bureau\Rag 13.04.25\test_implementation_conflicts.py", line 77, in setUp
    self.auth_service = AuthService(db_manager=self.db_manager, cache_manager=self.cache_manager)
                        ^^^^^^^^^^^^^^^^^^^^^^^^^^^^^^^^^^^^^^^^^^^^^^^^^^^^^^^^^^^^^^^^^^^^^^^^^
TypeError: AuthService.__init__() got an unexpected keyword argument 'cache_manager'

```

#### Error 3
```
Traceback (most recent call last):
  File "C:\Users\andri\OneDrive\Bureau\Rag 13.04.25\test_implementation_conflicts.py", line 77, in setUp
    self.auth_service = AuthService(db_manager=self.db_manager, cache_manager=self.cache_manager)
                        ^^^^^^^^^^^^^^^^^^^^^^^^^^^^^^^^^^^^^^^^^^^^^^^^^^^^^^^^^^^^^^^^^^^^^^^^^
TypeError: AuthService.__init__() got an unexpected keyword argument 'cache_manager'

```

#### Error 4
```
Traceback (most recent call last):
  File "C:\Users\andri\OneDrive\Bureau\Rag 13.04.25\test_implementation_conflicts.py", line 77, in setUp
    self.auth_service = AuthService(db_manager=self.db_manager, cache_manager=self.cache_manager)
                        ^^^^^^^^^^^^^^^^^^^^^^^^^^^^^^^^^^^^^^^^^^^^^^^^^^^^^^^^^^^^^^^^^^^^^^^^^
TypeError: AuthService.__init__() got an unexpected keyword argument 'cache_manager'

```

#### Error 5
```
Traceback (most recent call last):
  File "C:\Users\andri\OneDrive\Bureau\Rag 13.04.25\test_implementation_conflicts.py", line 77, in setUp
    self.auth_service = AuthService(db_manager=self.db_manager, cache_manager=self.cache_manager)
                        ^^^^^^^^^^^^^^^^^^^^^^^^^^^^^^^^^^^^^^^^^^^^^^^^^^^^^^^^^^^^^^^^^^^^^^^^^
TypeError: AuthService.__init__() got an unexpected keyword argument 'cache_manager'

```

#### Error 6
```
Traceback (most recent call last):
  File "C:\Users\andri\OneDrive\Bureau\Rag 13.04.25\test_implementation_conflicts.py", line 77, in setUp
    self.auth_service = AuthService(db_manager=self.db_manager, cache_manager=self.cache_manager)
                        ^^^^^^^^^^^^^^^^^^^^^^^^^^^^^^^^^^^^^^^^^^^^^^^^^^^^^^^^^^^^^^^^^^^^^^^^^
TypeError: AuthService.__init__() got an unexpected keyword argument 'cache_manager'

```

#### Error 7
```
Traceback (most recent call last):
  File "C:\Users\andri\OneDrive\Bureau\Rag 13.04.25\test_implementation_conflicts.py", line 77, in setUp
    self.auth_service = AuthService(db_manager=self.db_manager, cache_manager=self.cache_manager)
                        ^^^^^^^^^^^^^^^^^^^^^^^^^^^^^^^^^^^^^^^^^^^^^^^^^^^^^^^^^^^^^^^^^^^^^^^^^
TypeError: AuthService.__init__() got an unexpected keyword argument 'cache_manager'

```

#### Error 8
```
Traceback (most recent call last):
  File "C:\Users\andri\OneDrive\Bureau\Rag 13.04.25\test_implementation_conflicts.py", line 77, in setUp
    self.auth_service = AuthService(db_manager=self.db_manager, cache_manager=self.cache_manager)
                        ^^^^^^^^^^^^^^^^^^^^^^^^^^^^^^^^^^^^^^^^^^^^^^^^^^^^^^^^^^^^^^^^^^^^^^^^^
TypeError: AuthService.__init__() got an unexpected keyword argument 'cache_manager'

```

#### Error 9
```
Traceback (most recent call last):
  File "C:\Users\andri\OneDrive\Bureau\Rag 13.04.25\test_implementation_conflicts.py", line 77, in setUp
    self.auth_service = AuthService(db_manager=self.db_manager, cache_manager=self.cache_manager)
                        ^^^^^^^^^^^^^^^^^^^^^^^^^^^^^^^^^^^^^^^^^^^^^^^^^^^^^^^^^^^^^^^^^^^^^^^^^
TypeError: AuthService.__init__() got an unexpected keyword argument 'cache_manager'

```

#### Error 10
```
Traceback (most recent call last):
  File "C:\Users\andri\OneDrive\Bureau\Rag 13.04.25\test_implementation_conflicts.py", line 77, in setUp
    self.auth_service = AuthService(db_manager=self.db_manager, cache_manager=self.cache_manager)
                        ^^^^^^^^^^^^^^^^^^^^^^^^^^^^^^^^^^^^^^^^^^^^^^^^^^^^^^^^^^^^^^^^^^^^^^^^^
TypeError: AuthService.__init__() got an unexpected keyword argument 'cache_manager'

```
