# Implementation Test Report
Generated on: 2025-04-15 11:06:05

## Summary
- Total Tests: 8
- Failures: 0
- Errors: 8
- Overall Status: FAILED

## Test Details

### Errors

#### Error 1
```
Traceback (most recent call last):
  File "C:\Users\andri\OneDrive\Bureau\Rag 13.04.25\test_implementation_conflicts.py", line 67, in setUp
    self.testing_manager = TestingManager(
                           ^^^^^^^^^^^^^^^
TypeError: TestingManager.__init__() got an unexpected keyword argument 'test_path'

```

#### Error 2
```
Traceback (most recent call last):
  File "C:\Users\andri\OneDrive\Bureau\Rag 13.04.25\test_implementation_conflicts.py", line 67, in setUp
    self.testing_manager = TestingManager(
                           ^^^^^^^^^^^^^^^
TypeError: TestingManager.__init__() got an unexpected keyword argument 'test_path'

```

#### Error 3
```
Traceback (most recent call last):
  File "C:\Users\andri\OneDrive\Bureau\Rag 13.04.25\test_implementation_conflicts.py", line 67, in setUp
    self.testing_manager = TestingManager(
                           ^^^^^^^^^^^^^^^
TypeError: TestingManager.__init__() got an unexpected keyword argument 'test_path'

```

#### Error 4
```
Traceback (most recent call last):
  File "C:\Users\andri\OneDrive\Bureau\Rag 13.04.25\test_implementation_conflicts.py", line 67, in setUp
    self.testing_manager = TestingManager(
                           ^^^^^^^^^^^^^^^
TypeError: TestingManager.__init__() got an unexpected keyword argument 'test_path'

```

#### Error 5
```
Traceback (most recent call last):
  File "C:\Users\andri\OneDrive\Bureau\Rag 13.04.25\test_implementation_conflicts.py", line 67, in setUp
    self.testing_manager = TestingManager(
                           ^^^^^^^^^^^^^^^
TypeError: TestingManager.__init__() got an unexpected keyword argument 'test_path'

```

#### Error 6
```
Traceback (most recent call last):
  File "C:\Users\andri\OneDrive\Bureau\Rag 13.04.25\test_implementation_conflicts.py", line 67, in setUp
    self.testing_manager = TestingManager(
                           ^^^^^^^^^^^^^^^
TypeError: TestingManager.__init__() got an unexpected keyword argument 'test_path'

```

#### Error 7
```
Traceback (most recent call last):
  File "C:\Users\andri\OneDrive\Bureau\Rag 13.04.25\test_implementation_conflicts.py", line 67, in setUp
    self.testing_manager = TestingManager(
                           ^^^^^^^^^^^^^^^
TypeError: TestingManager.__init__() got an unexpected keyword argument 'test_path'

```

#### Error 8
```
Traceback (most recent call last):
  File "C:\Users\andri\OneDrive\Bureau\Rag 13.04.25\test_implementation_conflicts.py", line 67, in setUp
    self.testing_manager = TestingManager(
                           ^^^^^^^^^^^^^^^
TypeError: TestingManager.__init__() got an unexpected keyword argument 'test_path'

```
